Traceback (most recent call last):
  File "/Users/n960179/flaskapi2/venv/lib/python3.12/site-packages/urllib3/connectionpool.py", line 793, in urlopen
    response = self._make_request(
               ^^^^^^^^^^^^^^^^^^^
  File "/Users/n960179/flaskapi2/venv/lib/python3.12/site-packages/urllib3/connectionpool.py", line 491, in _make_request
    raise new_e
  File "/Users/n960179/flaskapi2/venv/lib/python3.12/site-packages/urllib3/connectionpool.py", line 467, in _make_request
    self._validate_conn(conn)
  File "/Users/n960179/flaskapi2/venv/lib/python3.12/site-packages/urllib3/connectionpool.py", line 1099, in _validate_conn
    conn.connect()
  File "/Users/n960179/flaskapi2/venv/lib/python3.12/site-packages/urllib3/connection.py", line 653, in connect
    sock_and_verified = _ssl_wrap_socket_and_match_hostname(
                        ^^^^^^^^^^^^^^^^^^^^^^^^^^^^^^^^^^^^
  File "/Users/n960179/flaskapi2/venv/lib/python3.12/site-packages/urllib3/connection.py", line 806, in _ssl_wrap_socket_and_match_hostname
    ssl_sock = ssl_wrap_socket(
               ^^^^^^^^^^^^^^^^
  File "/Users/n960179/flaskapi2/venv/lib/python3.12/site-packages/urllib3/util/ssl_.py", line 465, in ssl_wrap_socket
    ssl_sock = _ssl_wrap_socket_impl(sock, context, tls_in_tls, server_hostname)
               ^^^^^^^^^^^^^^^^^^^^^^^^^^^^^^^^^^^^^^^^^^^^^^^^^^^^^^^^^^^^^^^^^
  File "/Users/n960179/flaskapi2/venv/lib/python3.12/site-packages/urllib3/util/ssl_.py", line 509, in _ssl_wrap_socket_impl
    return ssl_context.wrap_socket(sock, server_hostname=server_hostname)
           ^^^^^^^^^^^^^^^^^^^^^^^^^^^^^^^^^^^^^^^^^^^^^^^^^^^^^^^^^^^^^^
  File "/opt/homebrew/Cellar/python@3.12/3.12.2_1/Frameworks/Python.framework/Versions/3.12/lib/python3.12/ssl.py", line 455, in wrap_socket
    return self.sslsocket_class._create(
           ^^^^^^^^^^^^^^^^^^^^^^^^^^^^^
  File "/opt/homebrew/Cellar/python@3.12/3.12.2_1/Frameworks/Python.framework/Versions/3.12/lib/python3.12/ssl.py", line 1042, in _create
    self.do_handshake()
  File "/opt/homebrew/Cellar/python@3.12/3.12.2_1/Frameworks/Python.framework/Versions/3.12/lib/python3.12/ssl.py", line 1320, in do_handshake
    self._sslobj.do_handshake()
ConnectionResetError: [Errno 54] Connection reset by peer

During handling of the above exception, another exception occurred:

Traceback (most recent call last):
  File "/Users/n960179/flaskapi2/venv/lib/python3.12/site-packages/requests/adapters.py", line 486, in send
    resp = conn.urlopen(
           ^^^^^^^^^^^^^
  File "/Users/n960179/flaskapi2/venv/lib/python3.12/site-packages/urllib3/connectionpool.py", line 847, in urlopen
    retries = retries.increment(
              ^^^^^^^^^^^^^^^^^^
  File "/Users/n960179/flaskapi2/venv/lib/python3.12/site-packages/urllib3/util/retry.py", line 470, in increment
    raise reraise(type(error), error, _stacktrace)
          ^^^^^^^^^^^^^^^^^^^^^^^^^^^^^^^^^^^^^^^^
  File "/Users/n960179/flaskapi2/venv/lib/python3.12/site-packages/urllib3/util/util.py", line 38, in reraise
    raise value.with_traceback(tb)
  File "/Users/n960179/flaskapi2/venv/lib/python3.12/site-packages/urllib3/connectionpool.py", line 793, in urlopen
    response = self._make_request(
               ^^^^^^^^^^^^^^^^^^^
  File "/Users/n960179/flaskapi2/venv/lib/python3.12/site-packages/urllib3/connectionpool.py", line 491, in _make_request
    raise new_e
  File "/Users/n960179/flaskapi2/venv/lib/python3.12/site-packages/urllib3/connectionpool.py", line 467, in _make_request
    self._validate_conn(conn)
  File "/Users/n960179/flaskapi2/venv/lib/python3.12/site-packages/urllib3/connectionpool.py", line 1099, in _validate_conn
    conn.connect()
  File "/Users/n960179/flaskapi2/venv/lib/python3.12/site-packages/urllib3/connection.py", line 653, in connect
    sock_and_verified = _ssl_wrap_socket_and_match_hostname(
                        ^^^^^^^^^^^^^^^^^^^^^^^^^^^^^^^^^^^^
  File "/Users/n960179/flaskapi2/venv/lib/python3.12/site-packages/urllib3/connection.py", line 806, in _ssl_wrap_socket_and_match_hostname
    ssl_sock = ssl_wrap_socket(
               ^^^^^^^^^^^^^^^^
  File "/Users/n960179/flaskapi2/venv/lib/python3.12/site-packages/urllib3/util/ssl_.py", line 465, in ssl_wrap_socket
    ssl_sock = _ssl_wrap_socket_impl(sock, context, tls_in_tls, server_hostname)
               ^^^^^^^^^^^^^^^^^^^^^^^^^^^^^^^^^^^^^^^^^^^^^^^^^^^^^^^^^^^^^^^^^
  File "/Users/n960179/flaskapi2/venv/lib/python3.12/site-packages/urllib3/util/ssl_.py", line 509, in _ssl_wrap_socket_impl
    return ssl_context.wrap_socket(sock, server_hostname=server_hostname)
           ^^^^^^^^^^^^^^^^^^^^^^^^^^^^^^^^^^^^^^^^^^^^^^^^^^^^^^^^^^^^^^
  File "/opt/homebrew/Cellar/python@3.12/3.12.2_1/Frameworks/Python.framework/Versions/3.12/lib/python3.12/ssl.py", line 455, in wrap_socket
    return self.sslsocket_class._create(
           ^^^^^^^^^^^^^^^^^^^^^^^^^^^^^
  File "/opt/homebrew/Cellar/python@3.12/3.12.2_1/Frameworks/Python.framework/Versions/3.12/lib/python3.12/ssl.py", line 1042, in _create
    self.do_handshake()
  File "/opt/homebrew/Cellar/python@3.12/3.12.2_1/Frameworks/Python.framework/Versions/3.12/lib/python3.12/ssl.py", line 1320, in do_handshake
    self._sslobj.do_handshake()
urllib3.exceptions.ProtocolError: ('Connection aborted.', ConnectionResetError(54, 'Connection reset by peer'))

During handling of the above exception, another exception occurred:

Traceback (most recent call last):
  File "/Users/n960179/test_flask1/upload.py", line 48, in <module>
    response = push_to_github(file_content, repo, filename)
               ^^^^^^^^^^^^^^^^^^^^^^^^^^^^^^^^^^^^^^^^^^^^
  File "/Users/n960179/test_flask1/upload.py", line 20, in push_to_github
    response = requests.get(url, headers=headers)
               ^^^^^^^^^^^^^^^^^^^^^^^^^^^^^^^^^^
  File "/Users/n960179/flaskapi2/venv/lib/python3.12/site-packages/requests/api.py", line 73, in get
    return request("get", url, params=params, **kwargs)
           ^^^^^^^^^^^^^^^^^^^^^^^^^^^^^^^^^^^^^^^^^^^^
  File "/Users/n960179/flaskapi2/venv/lib/python3.12/site-packages/requests/api.py", line 59, in request
    return session.request(method=method, url=url, **kwargs)
           ^^^^^^^^^^^^^^^^^^^^^^^^^^^^^^^^^^^^^^^^^^^^^^^^^
  File "/Users/n960179/flaskapi2/venv/lib/python3.12/site-packages/requests/sessions.py", line 589, in request
    resp = self.send(prep, **send_kwargs)
           ^^^^^^^^^^^^^^^^^^^^^^^^^^^^^^
  File "/Users/n960179/flaskapi2/venv/lib/python3.12/site-packages/requests/sessions.py", line 703, in send
    r = adapter.send(request, **kwargs)
        ^^^^^^^^^^^^^^^^^^^^^^^^^^^^^^^
  File "/Users/n960179/flaskapi2/venv/lib/python3.12/site-packages/requests/adapters.py", line 501, in send
    raise ConnectionError(err, request=request)
requests.exceptions.ConnectionError: ('Connection aborted.', ConnectionResetError(54, 'Connection reset by peer'))